<?xml version="1.0" ?>
<!-- =================================================================================== -->
<!-- |    This document was autogenerated by xacro from orne_alpha.xacro               | -->
<!-- |    EDITING THIS FILE BY HAND IS NOT RECOMMENDED                                 | -->
<!-- =================================================================================== -->
<robot name="orne_alpha" xmlns:controller="http://playerstage.sourceforge.net/gazebo/xmlschema/#controller" xmlns:interface="http://playerstage.sourceforge.net/gazebo/xmlschema/#interface" xmlns:sensor="http://playerstage.sourceforge.net/gazebo/xmlschema/#sensor" xmlns:xacro="http://ros.org/wiki/xacro">
  <material name="black">
    <color rgba="0.0 0.0 0.0 1.0"/>
  </material>
  <material name="blue">
    <color rgba="0.0 0.0 0.8 1.0"/>
  </material>
  <material name="green">
    <color rgba="0.0 0.8 0.0 1.0"/>
  </material>
  <material name="grey">
    <color rgba="0.2 0.2 0.2 1.0"/>
  </material>
  <material name="orange">
    <color rgba="1.0 0.4235294117647059 0.0392156862745098 1.0"/>
  </material>
  <material name="brown">
    <color rgba="0.8705882352941177 0.8117647058823529 0.7647058823529411 1.0"/>
  </material>
  <material name="red">
    <color rgba="0.8 0.0 0.0 1.0"/>
  </material>
  <material name="white">
    <color rgba="1.0 1.0 1.0 1.0"/>
  </material>
  <!-- ros_control plugin -->
  <gazebo>
    <plugin filename="libgazebo_ros_control.so" name="gazebo_ros_control">
      <robotSimType>icart_mini_gazebo/ICartMiniHWSim</robotSimType>
    </plugin>
  </gazebo>
  <!-- Left Wheel -->
  <gazebo reference="left_wheel">
    <mu1>1.0</mu1>
    <mu2>1.0</mu2>
    <kp>1000000.0</kp>
    <kd>100.0</kd>
    <minDepth>0.001</minDepth>
    <maxVel>1.0</maxVel>
    <material>Gazebo/Orange</material>
  </gazebo>
  <!-- Base Link -->
  <gazebo reference="base_link">
    <material>Gazebo/White</material>
  </gazebo>
  <!-- Right Wheel -->
  <gazebo reference="right_wheel">
    <mu1>1.0</mu1>
    <mu2>1.0</mu2>
    <kp>1000000.0</kp>
    <kd>100.0</kd>
    <minDepth>0.001</minDepth>
    <maxVel>1.0</maxVel>
    <material>Gazebo/Orange</material>
  </gazebo>
  <!-- Base Link -->
  <link name="base_link">
    <collision>
      <origin rpy="0 0 0" xyz="0 0 0.1"/>
      <geometry>
        <box size=".40 .45 .134"/>
      </geometry>
    </collision>
    <visual>
      <origin rpy="0 0 0" xyz="0.1 0 0.1"/>
      <geometry>
        <box size=".40 .45 .134"/>
      </geometry>
      <material name="orange"/>
    </visual>
    <collision>
      <origin rpy="0 0 0" xyz="0.005 0 0.305"/>
      <geometry>
        <box size=".376 .45 .134"/>
      </geometry>
    </collision>
    <visual>
      <origin rpy="0 0 0" xyz="0.005 0 0.305"/>
      <geometry>
        <box size=".376 .45 .134"/>
      </geometry>
      <material name="orange"/>
    </visual>
    <collision name="collision">
      <origin rpy="0 1.5707 1.5707" xyz="0.301 -0.141 0.075"/>
      <geometry>
        <cylinder length="0.03" radius="0.075"/>
      </geometry>
    </collision>
    <visual name="visual">
      <origin rpy="0 1.5707 1.5707" xyz="0.301 -0.141 0.075"/>
      <geometry>
        <cylinder length="0.03" radius="0.075"/>
      </geometry>
    </visual>
    <collision name="collision">
      <origin rpy="0 1.5707 1.5707" xyz="0.301 0.141 0.075"/>
      <geometry>
        <cylinder length="0.03" radius="0.075"/>
      </geometry>
    </collision>
    <visual name="visual">
      <origin rpy="0 1.5707 1.5707" xyz="0.301 0.141 0.075"/>
      <geometry>
        <cylinder length="0.03" radius="0.075"/>
      </geometry>
    </visual>
    <inertial>
      <mass value="15"/>
      <origin rpy="0 0 0" xyz="0 0 0"/>
      <inertia ixx="1" ixy="0" ixz="0" iyy="1" iyz="0" izz="1"/>
    </inertial>
  </link>
  <link name="visual_left_wheel">
    <visual name="visual">
      <origin rpy="0 1.5707 1.5707" xyz="0 0.0 0"/>
      <geometry>
        <cylinder length="0.03" radius="0.151"/>
      </geometry>
    </visual>
  </link>
  <joint name="visual_left_wheel_hinge" type="fixed">
    <origin rpy="0 0 0" xyz="-0.045 0.233 0.1518"/>
    <child link="visual_left_wheel">visual_left_wheel</child>
    <parent link="base_link">base_link</parent>
    <axis xyz="0 1 0"/>
  </joint>
  <link name="left_wheel">
    <collision name="collision">
      <origin rpy="0 1.5707 1.5707" xyz="0 0.0 0"/>
      <geometry>
        <cylinder length="0.03" radius="0.151"/>
      </geometry>
    </collision>
    <!--visual name="visual">
      <origin xyz="0 0.0 0" rpy="0 1.5707 1.5707"/>
      <geometry>
        <cylinder  length="0.03" radius="0.0725"/>
      </geometry>
    </visual-->
    <inertial>
      <mass value="1"/>
      <origin xyz="0 0.0 0"/>
      <inertia ixx="0.1" ixy="0" ixz="0" iyy="0.1" iyz="0" izz="0.1"/>
    </inertial>
  </link>
  <joint name="left_wheel_hinge" type="revolute">
    <origin rpy="0 0 0" xyz="-0.045 0.223 0.1518"/>
    <child link="left_wheel">left_wheel</child>
    <parent link="base_link">base_link</parent>
    <axis xyz="0 1 0"/>
    <limit effort="100" lower="-5000" upper="5000" velocity="100.0"/>
  </joint>
  <link name="visual_right_wheel">
    <visual name="visual">
      <origin rpy="0 1.5707 1.5707" xyz="0 0.0 0"/>
      <geometry>
        <cylinder length="0.03" radius="0.151"/>
      </geometry>
    </visual>
  </link>
  <joint name="visual_right_wheel_hinge" type="fixed">
    <origin rpy="0 0 0" xyz="-0.045 -0.223 0.1518"/>
    <child link="visual_right_wheel">visual_right_wheel</child>
    <parent link="base_link">base_link</parent>
    <axis xyz="0 1 0"/>
  </joint>
  <link name="right_wheel">
    <collision name="collision">
      <origin rpy="0 1.5707 1.5707" xyz="0 0.0 0"/>
      <geometry>
        <cylinder length="0.03" radius="0.151"/>
      </geometry>
    </collision>
    <!--visual name="visual">
      <origin xyz="0 0.0 0" rpy="0 1.5707 1.5707"/>
      <geometry>
        <cylinder  length="0.03" radius="0.0725"/>
      </geometry>
    </visual-->
    <inertial>
      <mass value="1"/>
      <origin xyz="0 0.0 0"/>
      <inertia ixx="0.1" ixy="0" ixz="0" iyy="0.1" iyz="0" izz="0.1"/>
    </inertial>
  </link>
  <joint name="right_wheel_hinge" type="revolute">
    <origin rpy="0 0 0" xyz="-0.045 -0.223 0.1518"/>
    <child link="right_wheel">right_wheel</child>
    <parent link="base_link">base_link</parent>
    <axis xyz="0 1 0"/>
    <limit effort="100" lower="-5000" upper="5000" velocity="100.0"/>
  </joint>
  <transmission name="tran1">
    <type>transmission_interface/SimpleTransmission</type>
    <joint name="left_wheel_hinge">
      <hardwareInterface>VelocityJointInterface</hardwareInterface>
    </joint>
    <actuator name="left_motor">
      <hardwareInterface>VelocityJointInterface</hardwareInterface>
      <mechanicalReduction>1</mechanicalReduction>
    </actuator>
  </transmission>
  <transmission name="tran2">
    <type>transmission_interface/SimpleTransmission</type>
    <joint name="right_wheel_hinge">
      <hardwareInterface>VelocityJointInterface</hardwareInterface>
    </joint>
    <actuator name="right_motor">
      <hardwareInterface>VelocityJointInterface</hardwareInterface>
      <mechanicalReduction>1</mechanicalReduction>
    </actuator>
  </transmission>
  <joint name="imu_joint" type="fixed">
    <axis xyz="1 0 0"/>
    <!--origin xyz="0 0 0.2825"/-->
    <origin rpy="0 3.14 0" xyz="-0.145 0.0 0.21"/>
    <parent link="base_link"/>
    <child link="imu"/>
  </joint>
  <link name="imu">
    <inertial>
      <mass value="0.001"/>
      <origin rpy="0 0 0" xyz="0 0 0"/>
      <inertia ixx="0.0001" ixy="0" ixz="0" iyy="0.000001" iyz="0" izz="0.0001"/>
    </inertial>
    <visual>
      <origin rpy="0 0 0" xyz="0 0 0"/>
      <geometry>
        <box size="0.05 0.05 0.05"/>
      </geometry>
    </visual>
    <collision>
      <origin rpy="0 0 0" xyz="0 0 0"/>
      <geometry>
        <box size="0.05 0.05 0.05"/>
      </geometry>
    </collision>
  </link>
  <gazebo>
    <plugin filename="libgazebo_ros_imu.so" name="ros_imu">
      <bodyName>imu_link</bodyName>
      <!-- bodyName always set base_link by URDF parser -->
      <topicName>imu_data</topicName>
      <serviceName>imu_service</serviceName>
      <gaussianNoise>0.005</gaussianNoise>
    </plugin>
  </gazebo>
  <joint name="velodyne_joint" type="fixed">
    <axis xyz="1 0 0"/>
    <origin rpy="0 0 -0.12" xyz="0.098 0.0 0.422"/>
    <parent link="base_link"/>
    <child link="velodyne"/>
  </joint>
  <link name="velodyne">
    <inertial>
      <mass value="0.001"/>
      <origin rpy="0 0 0" xyz="0 0 0"/>
      <inertia ixx="0.0001" ixy="0" ixz="0" iyy="0.000001" iyz="0" izz="0.0001"/>
    </inertial>
    <visual>
      <origin rpy="0 0 0.1" xyz="0 0 0"/>
      <geometry>
        <box size="0.05 0.05 0.05"/>
      </geometry>
    </visual>
    <collision>
      <origin rpy="0 0 0.1" xyz="0 0 0"/>
      <geometry>
        <box size="0.05 0.05 0.05"/>
      </geometry>
    </collision>
  </link>
</robot>

